[Thu Nov 16 16:44:24.751308 2017] [wsgi:error] [pid 11755:tid 139624844068608] Internal Server Error: /Testline_Details/login/
[Thu Nov 16 16:44:24.751385 2017] [wsgi:error] [pid 11755:tid 139624844068608] Traceback (most recent call last):
[Thu Nov 16 16:44:24.751390 2017] [wsgi:error] [pid 11755:tid 139624844068608]   File "/usr/local/lib/python3.5/dist-packages/django/db/backends/utils.py", line 64, in execute
[Thu Nov 16 16:44:24.751397 2017] [wsgi:error] [pid 11755:tid 139624844068608]     return self.cursor.execute(sql, params)
[Thu Nov 16 16:44:24.751401 2017] [wsgi:error] [pid 11755:tid 139624844068608]   File "/usr/local/lib/python3.5/dist-packages/django/db/backends/sqlite3/base.py", line 337, in execute
[Thu Nov 16 16:44:24.751405 2017] [wsgi:error] [pid 11755:tid 139624844068608]     return Database.Cursor.execute(self, query, params)
[Thu Nov 16 16:44:24.751408 2017] [wsgi:error] [pid 11755:tid 139624844068608] sqlite3.OperationalError: unable to open database file
[Thu Nov 16 16:44:24.751412 2017] [wsgi:error] [pid 11755:tid 139624844068608] 
[Thu Nov 16 16:44:24.751415 2017] [wsgi:error] [pid 11755:tid 139624844068608] The above exception was the direct cause of the following exception:
[Thu Nov 16 16:44:24.751418 2017] [wsgi:error] [pid 11755:tid 139624844068608] 
[Thu Nov 16 16:44:24.751421 2017] [wsgi:error] [pid 11755:tid 139624844068608] Traceback (most recent call last):
[Thu Nov 16 16:44:24.751425 2017] [wsgi:error] [pid 11755:tid 139624844068608]   File "/usr/local/lib/python3.5/dist-packages/django/core/handlers/exception.py", line 39, in inner
[Thu Nov 16 16:44:24.751431 2017] [wsgi:error] [pid 11755:tid 139624844068608]     response = get_response(request)
[Thu Nov 16 16:44:24.751436 2017] [wsgi:error] [pid 11755:tid 139624844068608]   File "/usr/local/lib/python3.5/dist-packages/django/core/handlers/base.py", line 249, in _legacy_get_response
[Thu Nov 16 16:44:24.751441 2017] [wsgi:error] [pid 11755:tid 139624844068608]     response = self._get_response(request)
[Thu Nov 16 16:44:24.751446 2017] [wsgi:error] [pid 11755:tid 139624844068608]   File "/usr/local/lib/python3.5/dist-packages/django/core/handlers/base.py", line 187, in _get_response
[Thu Nov 16 16:44:24.751451 2017] [wsgi:error] [pid 11755:tid 139624844068608]     response = self.process_exception_by_middleware(e, request)
[Thu Nov 16 16:44:24.751456 2017] [wsgi:error] [pid 11755:tid 139624844068608]   File "/usr/local/lib/python3.5/dist-packages/django/core/handlers/base.py", line 185, in _get_response
[Thu Nov 16 16:44:24.751461 2017] [wsgi:error] [pid 11755:tid 139624844068608]     response = wrapped_callback(request, *callback_args, **callback_kwargs)
[Thu Nov 16 16:44:24.751466 2017] [wsgi:error] [pid 11755:tid 139624844068608]   File "/home/sran/Django/SRANTLS/Testline_Details/views.py", line 73, in user_login
[Thu Nov 16 16:44:24.751471 2017] [wsgi:error] [pid 11755:tid 139624844068608]     login(request,user)
[Thu Nov 16 16:44:24.751475 2017] [wsgi:error] [pid 11755:tid 139624844068608]   File "/usr/local/lib/python3.5/dist-packages/django/contrib/auth/__init__.py", line 109, in login
[Thu Nov 16 16:44:24.751480 2017] [wsgi:error] [pid 11755:tid 139624844068608]     request.session.cycle_key()
[Thu Nov 16 16:44:24.751488 2017] [wsgi:error] [pid 11755:tid 139624844068608]   File "/usr/local/lib/python3.5/dist-packages/django/contrib/sessions/backends/base.py", line 311, in cycle_key
[Thu Nov 16 16:44:24.751493 2017] [wsgi:error] [pid 11755:tid 139624844068608]     self.create()
[Thu Nov 16 16:44:24.751498 2017] [wsgi:error] [pid 11755:tid 139624844068608]   File "/usr/local/lib/python3.5/dist-packages/django/contrib/sessions/backends/db.py", line 54, in create
[Thu Nov 16 16:44:24.751502 2017] [wsgi:error] [pid 11755:tid 139624844068608]     self.save(must_create=True)
[Thu Nov 16 16:44:24.751506 2017] [wsgi:error] [pid 11755:tid 139624844068608]   File "/usr/local/lib/python3.5/dist-packages/django/contrib/sessions/backends/db.py", line 87, in save
[Thu Nov 16 16:44:24.751511 2017] [wsgi:error] [pid 11755:tid 139624844068608]     obj.save(force_insert=must_create, force_update=not must_create, using=using)
[Thu Nov 16 16:44:24.751523 2017] [wsgi:error] [pid 11755:tid 139624844068608]   File "/usr/local/lib/python3.5/dist-packages/django/db/models/base.py", line 796, in save
[Thu Nov 16 16:44:24.751528 2017] [wsgi:error] [pid 11755:tid 139624844068608]     force_update=force_update, update_fields=update_fields)
[Thu Nov 16 16:44:24.751533 2017] [wsgi:error] [pid 11755:tid 139624844068608]   File "/usr/local/lib/python3.5/dist-packages/django/db/models/base.py", line 824, in save_base
[Thu Nov 16 16:44:24.751538 2017] [wsgi:error] [pid 11755:tid 139624844068608]     updated = self._save_table(raw, cls, force_insert, force_update, using, update_fields)
[Thu Nov 16 16:44:24.751543 2017] [wsgi:error] [pid 11755:tid 139624844068608]   File "/usr/local/lib/python3.5/dist-packages/django/db/models/base.py", line 908, in _save_table
[Thu Nov 16 16:44:24.751548 2017] [wsgi:error] [pid 11755:tid 139624844068608]     result = self._do_insert(cls._base_manager, using, fields, update_pk, raw)
[Thu Nov 16 16:44:24.751552 2017] [wsgi:error] [pid 11755:tid 139624844068608]   File "/usr/local/lib/python3.5/dist-packages/django/db/models/base.py", line 947, in _do_insert
[Thu Nov 16 16:44:24.751556 2017] [wsgi:error] [pid 11755:tid 139624844068608]     using=using, raw=raw)
[Thu Nov 16 16:44:24.751561 2017] [wsgi:error] [pid 11755:tid 139624844068608]   File "/usr/local/lib/python3.5/dist-packages/django/db/models/manager.py", line 85, in manager_method
[Thu Nov 16 16:44:24.751565 2017] [wsgi:error] [pid 11755:tid 139624844068608]     return getattr(self.get_queryset(), name)(*args, **kwargs)
[Thu Nov 16 16:44:24.751570 2017] [wsgi:error] [pid 11755:tid 139624844068608]   File "/usr/local/lib/python3.5/dist-packages/django/db/models/query.py", line 1045, in _insert
[Thu Nov 16 16:44:24.751574 2017] [wsgi:error] [pid 11755:tid 139624844068608]     return query.get_compiler(using=using).execute_sql(return_id)
[Thu Nov 16 16:44:24.751579 2017] [wsgi:error] [pid 11755:tid 139624844068608]   File "/usr/local/lib/python3.5/dist-packages/django/db/models/sql/compiler.py", line 1054, in execute_sql
[Thu Nov 16 16:44:24.751586 2017] [wsgi:error] [pid 11755:tid 139624844068608]     cursor.execute(sql, params)
[Thu Nov 16 16:44:24.751589 2017] [wsgi:error] [pid 11755:tid 139624844068608]   File "/usr/local/lib/python3.5/dist-packages/django/db/backends/utils.py", line 79, in execute
[Thu Nov 16 16:44:24.751592 2017] [wsgi:error] [pid 11755:tid 139624844068608]     return super(CursorDebugWrapper, self).execute(sql, params)
[Thu Nov 16 16:44:24.751596 2017] [wsgi:error] [pid 11755:tid 139624844068608]   File "/usr/local/lib/python3.5/dist-packages/django/db/backends/utils.py", line 64, in execute
[Thu Nov 16 16:44:24.751599 2017] [wsgi:error] [pid 11755:tid 139624844068608]     return self.cursor.execute(sql, params)
[Thu Nov 16 16:44:24.751602 2017] [wsgi:error] [pid 11755:tid 139624844068608]   File "/usr/local/lib/python3.5/dist-packages/django/db/utils.py", line 94, in __exit__
[Thu Nov 16 16:44:24.751605 2017] [wsgi:error] [pid 11755:tid 139624844068608]     six.reraise(dj_exc_type, dj_exc_value, traceback)
[Thu Nov 16 16:44:24.751608 2017] [wsgi:error] [pid 11755:tid 139624844068608]   File "/usr/local/lib/python3.5/dist-packages/django/utils/six.py", line 685, in reraise
[Thu Nov 16 16:44:24.751611 2017] [wsgi:error] [pid 11755:tid 139624844068608]     raise value.with_traceback(tb)
[Thu Nov 16 16:44:24.751614 2017] [wsgi:error] [pid 11755:tid 139624844068608]   File "/usr/local/lib/python3.5/dist-packages/django/db/backends/utils.py", line 64, in execute
[Thu Nov 16 16:44:24.751618 2017] [wsgi:error] [pid 11755:tid 139624844068608]     return self.cursor.execute(sql, params)
[Thu Nov 16 16:44:24.751621 2017] [wsgi:error] [pid 11755:tid 139624844068608]   File "/usr/local/lib/python3.5/dist-packages/django/db/backends/sqlite3/base.py", line 337, in execute
[Thu Nov 16 16:44:24.751624 2017] [wsgi:error] [pid 11755:tid 139624844068608]     return Database.Cursor.execute(self, query, params)
[Thu Nov 16 16:44:24.751635 2017] [wsgi:error] [pid 11755:tid 139624844068608] django.db.utils.OperationalError: unable to open database file
[Thu Nov 16 16:44:24.751645 2017] [wsgi:error] [pid 11755:tid 139624844068608] 
[Thu Nov 16 17:01:59.781082 2017] [wsgi:error] [pid 11755:tid 139624726464256] Internal Server Error: /Testline_Details/login/
[Thu Nov 16 17:01:59.781145 2017] [wsgi:error] [pid 11755:tid 139624726464256] Traceback (most recent call last):
[Thu Nov 16 17:01:59.781157 2017] [wsgi:error] [pid 11755:tid 139624726464256]   File "/usr/local/lib/python3.5/dist-packages/django/db/backends/utils.py", line 64, in execute
[Thu Nov 16 17:01:59.781163 2017] [wsgi:error] [pid 11755:tid 139624726464256]     return self.cursor.execute(sql, params)
[Thu Nov 16 17:01:59.781168 2017] [wsgi:error] [pid 11755:tid 139624726464256]   File "/usr/local/lib/python3.5/dist-packages/django/db/backends/sqlite3/base.py", line 337, in execute
[Thu Nov 16 17:01:59.781174 2017] [wsgi:error] [pid 11755:tid 139624726464256]     return Database.Cursor.execute(self, query, params)
[Thu Nov 16 17:01:59.781180 2017] [wsgi:error] [pid 11755:tid 139624726464256] sqlite3.OperationalError: unable to open database file
[Thu Nov 16 17:01:59.781185 2017] [wsgi:error] [pid 11755:tid 139624726464256] 
[Thu Nov 16 17:01:59.781190 2017] [wsgi:error] [pid 11755:tid 139624726464256] The above exception was the direct cause of the following exception:
[Thu Nov 16 17:01:59.781195 2017] [wsgi:error] [pid 11755:tid 139624726464256] 
[Thu Nov 16 17:01:59.781200 2017] [wsgi:error] [pid 11755:tid 139624726464256] Traceback (most recent call last):
[Thu Nov 16 17:01:59.781204 2017] [wsgi:error] [pid 11755:tid 139624726464256]   File "/usr/local/lib/python3.5/dist-packages/django/core/handlers/exception.py", line 39, in inner
[Thu Nov 16 17:01:59.781210 2017] [wsgi:error] [pid 11755:tid 139624726464256]     response = get_response(request)
[Thu Nov 16 17:01:59.781216 2017] [wsgi:error] [pid 11755:tid 139624726464256]   File "/usr/local/lib/python3.5/dist-packages/django/core/handlers/base.py", line 249, in _legacy_get_response
[Thu Nov 16 17:01:59.781222 2017] [wsgi:error] [pid 11755:tid 139624726464256]     response = self._get_response(request)
[Thu Nov 16 17:01:59.781228 2017] [wsgi:error] [pid 11755:tid 139624726464256]   File "/usr/local/lib/python3.5/dist-packages/django/core/handlers/base.py", line 187, in _get_response
[Thu Nov 16 17:01:59.781234 2017] [wsgi:error] [pid 11755:tid 139624726464256]     response = self.process_exception_by_middleware(e, request)
[Thu Nov 16 17:01:59.781241 2017] [wsgi:error] [pid 11755:tid 139624726464256]   File "/usr/local/lib/python3.5/dist-packages/django/core/handlers/base.py", line 185, in _get_response
[Thu Nov 16 17:01:59.781247 2017] [wsgi:error] [pid 11755:tid 139624726464256]     response = wrapped_callback(request, *callback_args, **callback_kwargs)
[Thu Nov 16 17:01:59.781254 2017] [wsgi:error] [pid 11755:tid 139624726464256]   File "/home/sran/Django/SRANTLS/Testline_Details/views.py", line 73, in user_login
[Thu Nov 16 17:01:59.781260 2017] [wsgi:error] [pid 11755:tid 139624726464256]     login(request,user)
[Thu Nov 16 17:01:59.781265 2017] [wsgi:error] [pid 11755:tid 139624726464256]   File "/usr/local/lib/python3.5/dist-packages/django/contrib/auth/__init__.py", line 109, in login
[Thu Nov 16 17:01:59.781271 2017] [wsgi:error] [pid 11755:tid 139624726464256]     request.session.cycle_key()
[Thu Nov 16 17:01:59.781276 2017] [wsgi:error] [pid 11755:tid 139624726464256]   File "/usr/local/lib/python3.5/dist-packages/django/contrib/sessions/backends/base.py", line 311, in cycle_key
[Thu Nov 16 17:01:59.781282 2017] [wsgi:error] [pid 11755:tid 139624726464256]     self.create()
[Thu Nov 16 17:01:59.781287 2017] [wsgi:error] [pid 11755:tid 139624726464256]   File "/usr/local/lib/python3.5/dist-packages/django/contrib/sessions/backends/db.py", line 54, in create
[Thu Nov 16 17:01:59.781292 2017] [wsgi:error] [pid 11755:tid 139624726464256]     self.save(must_create=True)
[Thu Nov 16 17:01:59.781298 2017] [wsgi:error] [pid 11755:tid 139624726464256]   File "/usr/local/lib/python3.5/dist-packages/django/contrib/sessions/backends/db.py", line 87, in save
[Thu Nov 16 17:01:59.781321 2017] [wsgi:error] [pid 11755:tid 139624726464256]     obj.save(force_insert=must_create, force_update=not must_create, using=using)
[Thu Nov 16 17:01:59.781329 2017] [wsgi:error] [pid 11755:tid 139624726464256]   File "/usr/local/lib/python3.5/dist-packages/django/db/models/base.py", line 796, in save
[Thu Nov 16 17:01:59.781336 2017] [wsgi:error] [pid 11755:tid 139624726464256]     force_update=force_update, update_fields=update_fields)
[Thu Nov 16 17:01:59.781341 2017] [wsgi:error] [pid 11755:tid 139624726464256]   File "/usr/local/lib/python3.5/dist-packages/django/db/models/base.py", line 824, in save_base
[Thu Nov 16 17:01:59.781346 2017] [wsgi:error] [pid 11755:tid 139624726464256]     updated = self._save_table(raw, cls, force_insert, force_update, using, update_fields)
[Thu Nov 16 17:01:59.781351 2017] [wsgi:error] [pid 11755:tid 139624726464256]   File "/usr/local/lib/python3.5/dist-packages/django/db/models/base.py", line 908, in _save_table
[Thu Nov 16 17:01:59.781357 2017] [wsgi:error] [pid 11755:tid 139624726464256]     result = self._do_insert(cls._base_manager, using, fields, update_pk, raw)
[Thu Nov 16 17:01:59.781362 2017] [wsgi:error] [pid 11755:tid 139624726464256]   File "/usr/local/lib/python3.5/dist-packages/django/db/models/base.py", line 947, in _do_insert
[Thu Nov 16 17:01:59.781366 2017] [wsgi:error] [pid 11755:tid 139624726464256]     using=using, raw=raw)
[Thu Nov 16 17:01:59.781369 2017] [wsgi:error] [pid 11755:tid 139624726464256]   File "/usr/local/lib/python3.5/dist-packages/django/db/models/manager.py", line 85, in manager_method
[Thu Nov 16 17:01:59.781372 2017] [wsgi:error] [pid 11755:tid 139624726464256]     return getattr(self.get_queryset(), name)(*args, **kwargs)
[Thu Nov 16 17:01:59.781376 2017] [wsgi:error] [pid 11755:tid 139624726464256]   File "/usr/local/lib/python3.5/dist-packages/django/db/models/query.py", line 1045, in _insert
[Thu Nov 16 17:01:59.781379 2017] [wsgi:error] [pid 11755:tid 139624726464256]     return query.get_compiler(using=using).execute_sql(return_id)
[Thu Nov 16 17:01:59.781383 2017] [wsgi:error] [pid 11755:tid 139624726464256]   File "/usr/local/lib/python3.5/dist-packages/django/db/models/sql/compiler.py", line 1054, in execute_sql
[Thu Nov 16 17:01:59.781386 2017] [wsgi:error] [pid 11755:tid 139624726464256]     cursor.execute(sql, params)
[Thu Nov 16 17:01:59.781389 2017] [wsgi:error] [pid 11755:tid 139624726464256]   File "/usr/local/lib/python3.5/dist-packages/django/db/backends/utils.py", line 79, in execute
[Thu Nov 16 17:01:59.781393 2017] [wsgi:error] [pid 11755:tid 139624726464256]     return super(CursorDebugWrapper, self).execute(sql, params)
[Thu Nov 16 17:01:59.781396 2017] [wsgi:error] [pid 11755:tid 139624726464256]   File "/usr/local/lib/python3.5/dist-packages/django/db/backends/utils.py", line 64, in execute
[Thu Nov 16 17:01:59.781399 2017] [wsgi:error] [pid 11755:tid 139624726464256]     return self.cursor.execute(sql, params)
[Thu Nov 16 17:01:59.781403 2017] [wsgi:error] [pid 11755:tid 139624726464256]   File "/usr/local/lib/python3.5/dist-packages/django/db/utils.py", line 94, in __exit__
[Thu Nov 16 17:01:59.781406 2017] [wsgi:error] [pid 11755:tid 139624726464256]     six.reraise(dj_exc_type, dj_exc_value, traceback)
[Thu Nov 16 17:01:59.781409 2017] [wsgi:error] [pid 11755:tid 139624726464256]   File "/usr/local/lib/python3.5/dist-packages/django/utils/six.py", line 685, in reraise
[Thu Nov 16 17:01:59.781413 2017] [wsgi:error] [pid 11755:tid 139624726464256]     raise value.with_traceback(tb)
[Thu Nov 16 17:01:59.781416 2017] [wsgi:error] [pid 11755:tid 139624726464256]   File "/usr/local/lib/python3.5/dist-packages/django/db/backends/utils.py", line 64, in execute
[Thu Nov 16 17:01:59.781423 2017] [wsgi:error] [pid 11755:tid 139624726464256]     return self.cursor.execute(sql, params)
[Thu Nov 16 17:01:59.781426 2017] [wsgi:error] [pid 11755:tid 139624726464256]   File "/usr/local/lib/python3.5/dist-packages/django/db/backends/sqlite3/base.py", line 337, in execute
[Thu Nov 16 17:01:59.781434 2017] [wsgi:error] [pid 11755:tid 139624726464256]     return Database.Cursor.execute(self, query, params)
[Thu Nov 16 17:01:59.781441 2017] [wsgi:error] [pid 11755:tid 139624726464256] django.db.utils.OperationalError: unable to open database file
[Thu Nov 16 17:01:59.781451 2017] [wsgi:error] [pid 11755:tid 139624726464256] 
[Thu Nov 16 18:27:43.816331 2017] [wsgi:error] [pid 12647:tid 140022750893824] Internal Server Error: /Testline_Details/login/
[Thu Nov 16 18:27:43.816398 2017] [wsgi:error] [pid 12647:tid 140022750893824] Traceback (most recent call last):
[Thu Nov 16 18:27:43.816410 2017] [wsgi:error] [pid 12647:tid 140022750893824]   File "/usr/local/lib/python3.5/dist-packages/django/db/backends/utils.py", line 64, in execute
[Thu Nov 16 18:27:43.816416 2017] [wsgi:error] [pid 12647:tid 140022750893824]     return self.cursor.execute(sql, params)
[Thu Nov 16 18:27:43.816421 2017] [wsgi:error] [pid 12647:tid 140022750893824]   File "/usr/local/lib/python3.5/dist-packages/django/db/backends/sqlite3/base.py", line 337, in execute
[Thu Nov 16 18:27:43.816427 2017] [wsgi:error] [pid 12647:tid 140022750893824]     return Database.Cursor.execute(self, query, params)
[Thu Nov 16 18:27:43.816432 2017] [wsgi:error] [pid 12647:tid 140022750893824] sqlite3.OperationalError: unable to open database file
[Thu Nov 16 18:27:43.816439 2017] [wsgi:error] [pid 12647:tid 140022750893824] 
[Thu Nov 16 18:27:43.816444 2017] [wsgi:error] [pid 12647:tid 140022750893824] The above exception was the direct cause of the following exception:
[Thu Nov 16 18:27:43.816449 2017] [wsgi:error] [pid 12647:tid 140022750893824] 
[Thu Nov 16 18:27:43.816454 2017] [wsgi:error] [pid 12647:tid 140022750893824] Traceback (most recent call last):
[Thu Nov 16 18:27:43.816460 2017] [wsgi:error] [pid 12647:tid 140022750893824]   File "/usr/local/lib/python3.5/dist-packages/django/core/handlers/exception.py", line 39, in inner
[Thu Nov 16 18:27:43.816465 2017] [wsgi:error] [pid 12647:tid 140022750893824]     response = get_response(request)
[Thu Nov 16 18:27:43.816470 2017] [wsgi:error] [pid 12647:tid 140022750893824]   File "/usr/local/lib/python3.5/dist-packages/django/core/handlers/base.py", line 249, in _legacy_get_response
[Thu Nov 16 18:27:43.816476 2017] [wsgi:error] [pid 12647:tid 140022750893824]     response = self._get_response(request)
[Thu Nov 16 18:27:43.816482 2017] [wsgi:error] [pid 12647:tid 140022750893824]   File "/usr/local/lib/python3.5/dist-packages/django/core/handlers/base.py", line 187, in _get_response
[Thu Nov 16 18:27:43.816487 2017] [wsgi:error] [pid 12647:tid 140022750893824]     response = self.process_exception_by_middleware(e, request)
[Thu Nov 16 18:27:43.816492 2017] [wsgi:error] [pid 12647:tid 140022750893824]   File "/usr/local/lib/python3.5/dist-packages/django/core/handlers/base.py", line 185, in _get_response
[Thu Nov 16 18:27:43.816498 2017] [wsgi:error] [pid 12647:tid 140022750893824]     response = wrapped_callback(request, *callback_args, **callback_kwargs)
[Thu Nov 16 18:27:43.816504 2017] [wsgi:error] [pid 12647:tid 140022750893824]   File "/home/sran/Django/SRANTLS/Testline_Details/views.py", line 73, in user_login
[Thu Nov 16 18:27:43.816509 2017] [wsgi:error] [pid 12647:tid 140022750893824]     login(request,user)
[Thu Nov 16 18:27:43.816515 2017] [wsgi:error] [pid 12647:tid 140022750893824]   File "/usr/local/lib/python3.5/dist-packages/django/contrib/auth/__init__.py", line 109, in login
[Thu Nov 16 18:27:43.816521 2017] [wsgi:error] [pid 12647:tid 140022750893824]     request.session.cycle_key()
[Thu Nov 16 18:27:43.816526 2017] [wsgi:error] [pid 12647:tid 140022750893824]   File "/usr/local/lib/python3.5/dist-packages/django/contrib/sessions/backends/base.py", line 311, in cycle_key
[Thu Nov 16 18:27:43.816531 2017] [wsgi:error] [pid 12647:tid 140022750893824]     self.create()
[Thu Nov 16 18:27:43.816537 2017] [wsgi:error] [pid 12647:tid 140022750893824]   File "/usr/local/lib/python3.5/dist-packages/django/contrib/sessions/backends/db.py", line 54, in create
[Thu Nov 16 18:27:43.816557 2017] [wsgi:error] [pid 12647:tid 140022750893824]     self.save(must_create=True)
[Thu Nov 16 18:27:43.816562 2017] [wsgi:error] [pid 12647:tid 140022750893824]   File "/usr/local/lib/python3.5/dist-packages/django/contrib/sessions/backends/db.py", line 87, in save
[Thu Nov 16 18:27:43.816568 2017] [wsgi:error] [pid 12647:tid 140022750893824]     obj.save(force_insert=must_create, force_update=not must_create, using=using)
[Thu Nov 16 18:27:43.816572 2017] [wsgi:error] [pid 12647:tid 140022750893824]   File "/usr/local/lib/python3.5/dist-packages/django/db/models/base.py", line 796, in save
[Thu Nov 16 18:27:43.816578 2017] [wsgi:error] [pid 12647:tid 140022750893824]     force_update=force_update, update_fields=update_fields)
[Thu Nov 16 18:27:43.816583 2017] [wsgi:error] [pid 12647:tid 140022750893824]   File "/usr/local/lib/python3.5/dist-packages/django/db/models/base.py", line 824, in save_base
[Thu Nov 16 18:27:43.816588 2017] [wsgi:error] [pid 12647:tid 140022750893824]     updated = self._save_table(raw, cls, force_insert, force_update, using, update_fields)
[Thu Nov 16 18:27:43.816593 2017] [wsgi:error] [pid 12647:tid 140022750893824]   File "/usr/local/lib/python3.5/dist-packages/django/db/models/base.py", line 908, in _save_table
[Thu Nov 16 18:27:43.816599 2017] [wsgi:error] [pid 12647:tid 140022750893824]     result = self._do_insert(cls._base_manager, using, fields, update_pk, raw)
[Thu Nov 16 18:27:43.816604 2017] [wsgi:error] [pid 12647:tid 140022750893824]   File "/usr/local/lib/python3.5/dist-packages/django/db/models/base.py", line 947, in _do_insert
[Thu Nov 16 18:27:43.816609 2017] [wsgi:error] [pid 12647:tid 140022750893824]     using=using, raw=raw)
[Thu Nov 16 18:27:43.816615 2017] [wsgi:error] [pid 12647:tid 140022750893824]   File "/usr/local/lib/python3.5/dist-packages/django/db/models/manager.py", line 85, in manager_method
[Thu Nov 16 18:27:43.816620 2017] [wsgi:error] [pid 12647:tid 140022750893824]     return getattr(self.get_queryset(), name)(*args, **kwargs)
[Thu Nov 16 18:27:43.816624 2017] [wsgi:error] [pid 12647:tid 140022750893824]   File "/usr/local/lib/python3.5/dist-packages/django/db/models/query.py", line 1045, in _insert
[Thu Nov 16 18:27:43.816627 2017] [wsgi:error] [pid 12647:tid 140022750893824]     return query.get_compiler(using=using).execute_sql(return_id)
[Thu Nov 16 18:27:43.816631 2017] [wsgi:error] [pid 12647:tid 140022750893824]   File "/usr/local/lib/python3.5/dist-packages/django/db/models/sql/compiler.py", line 1054, in execute_sql
[Thu Nov 16 18:27:43.816634 2017] [wsgi:error] [pid 12647:tid 140022750893824]     cursor.execute(sql, params)
[Thu Nov 16 18:27:43.816637 2017] [wsgi:error] [pid 12647:tid 140022750893824]   File "/usr/local/lib/python3.5/dist-packages/django/db/backends/utils.py", line 79, in execute
[Thu Nov 16 18:27:43.816641 2017] [wsgi:error] [pid 12647:tid 140022750893824]     return super(CursorDebugWrapper, self).execute(sql, params)
[Thu Nov 16 18:27:43.816644 2017] [wsgi:error] [pid 12647:tid 140022750893824]   File "/usr/local/lib/python3.5/dist-packages/django/db/backends/utils.py", line 64, in execute
[Thu Nov 16 18:27:43.816648 2017] [wsgi:error] [pid 12647:tid 140022750893824]     return self.cursor.execute(sql, params)
[Thu Nov 16 18:27:43.816651 2017] [wsgi:error] [pid 12647:tid 140022750893824]   File "/usr/local/lib/python3.5/dist-packages/django/db/utils.py", line 94, in __exit__
[Thu Nov 16 18:27:43.816658 2017] [wsgi:error] [pid 12647:tid 140022750893824]     six.reraise(dj_exc_type, dj_exc_value, traceback)
[Thu Nov 16 18:27:43.816661 2017] [wsgi:error] [pid 12647:tid 140022750893824]   File "/usr/local/lib/python3.5/dist-packages/django/utils/six.py", line 685, in reraise
[Thu Nov 16 18:27:43.816664 2017] [wsgi:error] [pid 12647:tid 140022750893824]     raise value.with_traceback(tb)
[Thu Nov 16 18:27:43.816667 2017] [wsgi:error] [pid 12647:tid 140022750893824]   File "/usr/local/lib/python3.5/dist-packages/django/db/backends/utils.py", line 64, in execute
[Thu Nov 16 18:27:43.816675 2017] [wsgi:error] [pid 12647:tid 140022750893824]     return self.cursor.execute(sql, params)
[Thu Nov 16 18:27:43.816678 2017] [wsgi:error] [pid 12647:tid 140022750893824]   File "/usr/local/lib/python3.5/dist-packages/django/db/backends/sqlite3/base.py", line 337, in execute
[Thu Nov 16 18:27:43.816682 2017] [wsgi:error] [pid 12647:tid 140022750893824]     return Database.Cursor.execute(self, query, params)
[Thu Nov 16 18:27:43.816688 2017] [wsgi:error] [pid 12647:tid 140022750893824] django.db.utils.OperationalError: unable to open database file
[Thu Nov 16 18:27:43.816699 2017] [wsgi:error] [pid 12647:tid 140022750893824] 
[Thu Nov 16 18:29:07.361929 2017] [wsgi:error] [pid 12647:tid 140022750893824] Internal Server Error: /Testline_Details/login/
[Thu Nov 16 18:29:07.361998 2017] [wsgi:error] [pid 12647:tid 140022750893824] Traceback (most recent call last):
[Thu Nov 16 18:29:07.362007 2017] [wsgi:error] [pid 12647:tid 140022750893824]   File "/usr/local/lib/python3.5/dist-packages/django/db/backends/utils.py", line 64, in execute
[Thu Nov 16 18:29:07.362017 2017] [wsgi:error] [pid 12647:tid 140022750893824]     return self.cursor.execute(sql, params)
[Thu Nov 16 18:29:07.362023 2017] [wsgi:error] [pid 12647:tid 140022750893824]   File "/usr/local/lib/python3.5/dist-packages/django/db/backends/sqlite3/base.py", line 337, in execute
[Thu Nov 16 18:29:07.362029 2017] [wsgi:error] [pid 12647:tid 140022750893824]     return Database.Cursor.execute(self, query, params)
[Thu Nov 16 18:29:07.362035 2017] [wsgi:error] [pid 12647:tid 140022750893824] sqlite3.OperationalError: unable to open database file
[Thu Nov 16 18:29:07.362067 2017] [wsgi:error] [pid 12647:tid 140022750893824] 
[Thu Nov 16 18:29:07.362074 2017] [wsgi:error] [pid 12647:tid 140022750893824] The above exception was the direct cause of the following exception:
[Thu Nov 16 18:29:07.362079 2017] [wsgi:error] [pid 12647:tid 140022750893824] 
[Thu Nov 16 18:29:07.362084 2017] [wsgi:error] [pid 12647:tid 140022750893824] Traceback (most recent call last):
[Thu Nov 16 18:29:07.362089 2017] [wsgi:error] [pid 12647:tid 140022750893824]   File "/usr/local/lib/python3.5/dist-packages/django/core/handlers/exception.py", line 39, in inner
[Thu Nov 16 18:29:07.362095 2017] [wsgi:error] [pid 12647:tid 140022750893824]     response = get_response(request)
[Thu Nov 16 18:29:07.362100 2017] [wsgi:error] [pid 12647:tid 140022750893824]   File "/usr/local/lib/python3.5/dist-packages/django/core/handlers/base.py", line 249, in _legacy_get_response
[Thu Nov 16 18:29:07.362106 2017] [wsgi:error] [pid 12647:tid 140022750893824]     response = self._get_response(request)
[Thu Nov 16 18:29:07.362112 2017] [wsgi:error] [pid 12647:tid 140022750893824]   File "/usr/local/lib/python3.5/dist-packages/django/core/handlers/base.py", line 187, in _get_response
[Thu Nov 16 18:29:07.362119 2017] [wsgi:error] [pid 12647:tid 140022750893824]     response = self.process_exception_by_middleware(e, request)
[Thu Nov 16 18:29:07.362125 2017] [wsgi:error] [pid 12647:tid 140022750893824]   File "/usr/local/lib/python3.5/dist-packages/django/core/handlers/base.py", line 185, in _get_response
[Thu Nov 16 18:29:07.362131 2017] [wsgi:error] [pid 12647:tid 140022750893824]     response = wrapped_callback(request, *callback_args, **callback_kwargs)
[Thu Nov 16 18:29:07.362136 2017] [wsgi:error] [pid 12647:tid 140022750893824]   File "/home/sran/Django/SRANTLS/Testline_Details/views.py", line 73, in user_login
[Thu Nov 16 18:29:07.362142 2017] [wsgi:error] [pid 12647:tid 140022750893824]     login(request,user)
[Thu Nov 16 18:29:07.362147 2017] [wsgi:error] [pid 12647:tid 140022750893824]   File "/usr/local/lib/python3.5/dist-packages/django/contrib/auth/__init__.py", line 109, in login
[Thu Nov 16 18:29:07.362152 2017] [wsgi:error] [pid 12647:tid 140022750893824]     request.session.cycle_key()
[Thu Nov 16 18:29:07.362158 2017] [wsgi:error] [pid 12647:tid 140022750893824]   File "/usr/local/lib/python3.5/dist-packages/django/contrib/sessions/backends/base.py", line 311, in cycle_key
[Thu Nov 16 18:29:07.362181 2017] [wsgi:error] [pid 12647:tid 140022750893824]     self.create()
[Thu Nov 16 18:29:07.362188 2017] [wsgi:error] [pid 12647:tid 140022750893824]   File "/usr/local/lib/python3.5/dist-packages/django/contrib/sessions/backends/db.py", line 54, in create
[Thu Nov 16 18:29:07.362194 2017] [wsgi:error] [pid 12647:tid 140022750893824]     self.save(must_create=True)
[Thu Nov 16 18:29:07.362200 2017] [wsgi:error] [pid 12647:tid 140022750893824]   File "/usr/local/lib/python3.5/dist-packages/django/contrib/sessions/backends/db.py", line 87, in save
[Thu Nov 16 18:29:07.362205 2017] [wsgi:error] [pid 12647:tid 140022750893824]     obj.save(force_insert=must_create, force_update=not must_create, using=using)
[Thu Nov 16 18:29:07.362210 2017] [wsgi:error] [pid 12647:tid 140022750893824]   File "/usr/local/lib/python3.5/dist-packages/django/db/models/base.py", line 796, in save
[Thu Nov 16 18:29:07.362220 2017] [wsgi:error] [pid 12647:tid 140022750893824]     force_update=force_update, update_fields=update_fields)
[Thu Nov 16 18:29:07.362225 2017] [wsgi:error] [pid 12647:tid 140022750893824]   File "/usr/local/lib/python3.5/dist-packages/django/db/models/base.py", line 824, in save_base
[Thu Nov 16 18:29:07.362230 2017] [wsgi:error] [pid 12647:tid 140022750893824]     updated = self._save_table(raw, cls, force_insert, force_update, using, update_fields)
[Thu Nov 16 18:29:07.362234 2017] [wsgi:error] [pid 12647:tid 140022750893824]   File "/usr/local/lib/python3.5/dist-packages/django/db/models/base.py", line 908, in _save_table
[Thu Nov 16 18:29:07.362240 2017] [wsgi:error] [pid 12647:tid 140022750893824]     result = self._do_insert(cls._base_manager, using, fields, update_pk, raw)
[Thu Nov 16 18:29:07.362244 2017] [wsgi:error] [pid 12647:tid 140022750893824]   File "/usr/local/lib/python3.5/dist-packages/django/db/models/base.py", line 947, in _do_insert
[Thu Nov 16 18:29:07.362249 2017] [wsgi:error] [pid 12647:tid 140022750893824]     using=using, raw=raw)
[Thu Nov 16 18:29:07.362254 2017] [wsgi:error] [pid 12647:tid 140022750893824]   File "/usr/local/lib/python3.5/dist-packages/django/db/models/manager.py", line 85, in manager_method
[Thu Nov 16 18:29:07.362259 2017] [wsgi:error] [pid 12647:tid 140022750893824]     return getattr(self.get_queryset(), name)(*args, **kwargs)
[Thu Nov 16 18:29:07.362264 2017] [wsgi:error] [pid 12647:tid 140022750893824]   File "/usr/local/lib/python3.5/dist-packages/django/db/models/query.py", line 1045, in _insert
[Thu Nov 16 18:29:07.362271 2017] [wsgi:error] [pid 12647:tid 140022750893824]     return query.get_compiler(using=using).execute_sql(return_id)
[Thu Nov 16 18:29:07.362275 2017] [wsgi:error] [pid 12647:tid 140022750893824]   File "/usr/local/lib/python3.5/dist-packages/django/db/models/sql/compiler.py", line 1054, in execute_sql
[Thu Nov 16 18:29:07.362280 2017] [wsgi:error] [pid 12647:tid 140022750893824]     cursor.execute(sql, params)
[Thu Nov 16 18:29:07.362285 2017] [wsgi:error] [pid 12647:tid 140022750893824]   File "/usr/local/lib/python3.5/dist-packages/django/db/backends/utils.py", line 79, in execute
[Thu Nov 16 18:29:07.362290 2017] [wsgi:error] [pid 12647:tid 140022750893824]     return super(CursorDebugWrapper, self).execute(sql, params)
[Thu Nov 16 18:29:07.362294 2017] [wsgi:error] [pid 12647:tid 140022750893824]   File "/usr/local/lib/python3.5/dist-packages/django/db/backends/utils.py", line 64, in execute
[Thu Nov 16 18:29:07.362299 2017] [wsgi:error] [pid 12647:tid 140022750893824]     return self.cursor.execute(sql, params)
[Thu Nov 16 18:29:07.362304 2017] [wsgi:error] [pid 12647:tid 140022750893824]   File "/usr/local/lib/python3.5/dist-packages/django/db/utils.py", line 94, in __exit__
[Thu Nov 16 18:29:07.362309 2017] [wsgi:error] [pid 12647:tid 140022750893824]     six.reraise(dj_exc_type, dj_exc_value, traceback)
[Thu Nov 16 18:29:07.362314 2017] [wsgi:error] [pid 12647:tid 140022750893824]   File "/usr/local/lib/python3.5/dist-packages/django/utils/six.py", line 685, in reraise
[Thu Nov 16 18:29:07.362325 2017] [wsgi:error] [pid 12647:tid 140022750893824]     raise value.with_traceback(tb)
[Thu Nov 16 18:29:07.362330 2017] [wsgi:error] [pid 12647:tid 140022750893824]   File "/usr/local/lib/python3.5/dist-packages/django/db/backends/utils.py", line 64, in execute
[Thu Nov 16 18:29:07.362335 2017] [wsgi:error] [pid 12647:tid 140022750893824]     return self.cursor.execute(sql, params)
[Thu Nov 16 18:29:07.362341 2017] [wsgi:error] [pid 12647:tid 140022750893824]   File "/usr/local/lib/python3.5/dist-packages/django/db/backends/sqlite3/base.py", line 337, in execute
[Thu Nov 16 18:29:07.362345 2017] [wsgi:error] [pid 12647:tid 140022750893824]     return Database.Cursor.execute(self, query, params)
[Thu Nov 16 18:29:07.362351 2017] [wsgi:error] [pid 12647:tid 140022750893824] django.db.utils.OperationalError: unable to open database file
[Thu Nov 16 18:29:07.362361 2017] [wsgi:error] [pid 12647:tid 140022750893824] 
[Thu Nov 16 18:29:18.573572 2017] [wsgi:error] [pid 12647:tid 140022633289472] Internal Server Error: /Testline_Details/login/
[Thu Nov 16 18:29:18.573635 2017] [wsgi:error] [pid 12647:tid 140022633289472] Traceback (most recent call last):
[Thu Nov 16 18:29:18.573640 2017] [wsgi:error] [pid 12647:tid 140022633289472]   File "/usr/local/lib/python3.5/dist-packages/django/db/backends/utils.py", line 64, in execute
[Thu Nov 16 18:29:18.573647 2017] [wsgi:error] [pid 12647:tid 140022633289472]     return self.cursor.execute(sql, params)
[Thu Nov 16 18:29:18.573651 2017] [wsgi:error] [pid 12647:tid 140022633289472]   File "/usr/local/lib/python3.5/dist-packages/django/db/backends/sqlite3/base.py", line 337, in execute
[Thu Nov 16 18:29:18.573654 2017] [wsgi:error] [pid 12647:tid 140022633289472]     return Database.Cursor.execute(self, query, params)
[Thu Nov 16 18:29:18.573658 2017] [wsgi:error] [pid 12647:tid 140022633289472] sqlite3.OperationalError: unable to open database file
[Thu Nov 16 18:29:18.573661 2017] [wsgi:error] [pid 12647:tid 140022633289472] 
[Thu Nov 16 18:29:18.573664 2017] [wsgi:error] [pid 12647:tid 140022633289472] The above exception was the direct cause of the following exception:
[Thu Nov 16 18:29:18.573668 2017] [wsgi:error] [pid 12647:tid 140022633289472] 
[Thu Nov 16 18:29:18.573671 2017] [wsgi:error] [pid 12647:tid 140022633289472] Traceback (most recent call last):
[Thu Nov 16 18:29:18.573674 2017] [wsgi:error] [pid 12647:tid 140022633289472]   File "/usr/local/lib/python3.5/dist-packages/django/core/handlers/exception.py", line 39, in inner
[Thu Nov 16 18:29:18.573678 2017] [wsgi:error] [pid 12647:tid 140022633289472]     response = get_response(request)
[Thu Nov 16 18:29:18.573681 2017] [wsgi:error] [pid 12647:tid 140022633289472]   File "/usr/local/lib/python3.5/dist-packages/django/core/handlers/base.py", line 249, in _legacy_get_response
[Thu Nov 16 18:29:18.573685 2017] [wsgi:error] [pid 12647:tid 140022633289472]     response = self._get_response(request)
[Thu Nov 16 18:29:18.573688 2017] [wsgi:error] [pid 12647:tid 140022633289472]   File "/usr/local/lib/python3.5/dist-packages/django/core/handlers/base.py", line 187, in _get_response
[Thu Nov 16 18:29:18.573692 2017] [wsgi:error] [pid 12647:tid 140022633289472]     response = self.process_exception_by_middleware(e, request)
[Thu Nov 16 18:29:18.573695 2017] [wsgi:error] [pid 12647:tid 140022633289472]   File "/usr/local/lib/python3.5/dist-packages/django/core/handlers/base.py", line 185, in _get_response
[Thu Nov 16 18:29:18.573700 2017] [wsgi:error] [pid 12647:tid 140022633289472]     response = wrapped_callback(request, *callback_args, **callback_kwargs)
[Thu Nov 16 18:29:18.573705 2017] [wsgi:error] [pid 12647:tid 140022633289472]   File "/home/sran/Django/SRANTLS/Testline_Details/views.py", line 73, in user_login
[Thu Nov 16 18:29:18.573710 2017] [wsgi:error] [pid 12647:tid 140022633289472]     login(request,user)
[Thu Nov 16 18:29:18.573715 2017] [wsgi:error] [pid 12647:tid 140022633289472]   File "/usr/local/lib/python3.5/dist-packages/django/contrib/auth/__init__.py", line 109, in login
[Thu Nov 16 18:29:18.573737 2017] [wsgi:error] [pid 12647:tid 140022633289472]     request.session.cycle_key()
[Thu Nov 16 18:29:18.573743 2017] [wsgi:error] [pid 12647:tid 140022633289472]   File "/usr/local/lib/python3.5/dist-packages/django/contrib/sessions/backends/base.py", line 311, in cycle_key
[Thu Nov 16 18:29:18.573748 2017] [wsgi:error] [pid 12647:tid 140022633289472]     self.create()
[Thu Nov 16 18:29:18.573753 2017] [wsgi:error] [pid 12647:tid 140022633289472]   File "/usr/local/lib/python3.5/dist-packages/django/contrib/sessions/backends/db.py", line 54, in create
[Thu Nov 16 18:29:18.573758 2017] [wsgi:error] [pid 12647:tid 140022633289472]     self.save(must_create=True)
[Thu Nov 16 18:29:18.573763 2017] [wsgi:error] [pid 12647:tid 140022633289472]   File "/usr/local/lib/python3.5/dist-packages/django/contrib/sessions/backends/db.py", line 87, in save
[Thu Nov 16 18:29:18.573768 2017] [wsgi:error] [pid 12647:tid 140022633289472]     obj.save(force_insert=must_create, force_update=not must_create, using=using)
[Thu Nov 16 18:29:18.573774 2017] [wsgi:error] [pid 12647:tid 140022633289472]   File "/usr/local/lib/python3.5/dist-packages/django/db/models/base.py", line 796, in save
[Thu Nov 16 18:29:18.573778 2017] [wsgi:error] [pid 12647:tid 140022633289472]     force_update=force_update, update_fields=update_fields)
[Thu Nov 16 18:29:18.573784 2017] [wsgi:error] [pid 12647:tid 140022633289472]   File "/usr/local/lib/python3.5/dist-packages/django/db/models/base.py", line 824, in save_base
[Thu Nov 16 18:29:18.573789 2017] [wsgi:error] [pid 12647:tid 140022633289472]     updated = self._save_table(raw, cls, force_insert, force_update, using, update_fields)
[Thu Nov 16 18:29:18.573794 2017] [wsgi:error] [pid 12647:tid 140022633289472]   File "/usr/local/lib/python3.5/dist-packages/django/db/models/base.py", line 908, in _save_table
[Thu Nov 16 18:29:18.573800 2017] [wsgi:error] [pid 12647:tid 140022633289472]     result = self._do_insert(cls._base_manager, using, fields, update_pk, raw)
[Thu Nov 16 18:29:18.573805 2017] [wsgi:error] [pid 12647:tid 140022633289472]   File "/usr/local/lib/python3.5/dist-packages/django/db/models/base.py", line 947, in _do_insert
[Thu Nov 16 18:29:18.573810 2017] [wsgi:error] [pid 12647:tid 140022633289472]     using=using, raw=raw)
[Thu Nov 16 18:29:18.573815 2017] [wsgi:error] [pid 12647:tid 140022633289472]   File "/usr/local/lib/python3.5/dist-packages/django/db/models/manager.py", line 85, in manager_method
[Thu Nov 16 18:29:18.573821 2017] [wsgi:error] [pid 12647:tid 140022633289472]     return getattr(self.get_queryset(), name)(*args, **kwargs)
[Thu Nov 16 18:29:18.573826 2017] [wsgi:error] [pid 12647:tid 140022633289472]   File "/usr/local/lib/python3.5/dist-packages/django/db/models/query.py", line 1045, in _insert
[Thu Nov 16 18:29:18.573831 2017] [wsgi:error] [pid 12647:tid 140022633289472]     return query.get_compiler(using=using).execute_sql(return_id)
[Thu Nov 16 18:29:18.573836 2017] [wsgi:error] [pid 12647:tid 140022633289472]   File "/usr/local/lib/python3.5/dist-packages/django/db/models/sql/compiler.py", line 1054, in execute_sql
[Thu Nov 16 18:29:18.573843 2017] [wsgi:error] [pid 12647:tid 140022633289472]     cursor.execute(sql, params)
[Thu Nov 16 18:29:18.573848 2017] [wsgi:error] [pid 12647:tid 140022633289472]   File "/usr/local/lib/python3.5/dist-packages/django/db/backends/utils.py", line 79, in execute
[Thu Nov 16 18:29:18.573853 2017] [wsgi:error] [pid 12647:tid 140022633289472]     return super(CursorDebugWrapper, self).execute(sql, params)
[Thu Nov 16 18:29:18.573859 2017] [wsgi:error] [pid 12647:tid 140022633289472]   File "/usr/local/lib/python3.5/dist-packages/django/db/backends/utils.py", line 64, in execute
[Thu Nov 16 18:29:18.573864 2017] [wsgi:error] [pid 12647:tid 140022633289472]     return self.cursor.execute(sql, params)
[Thu Nov 16 18:29:18.573869 2017] [wsgi:error] [pid 12647:tid 140022633289472]   File "/usr/local/lib/python3.5/dist-packages/django/db/utils.py", line 94, in __exit__
[Thu Nov 16 18:29:18.573874 2017] [wsgi:error] [pid 12647:tid 140022633289472]     six.reraise(dj_exc_type, dj_exc_value, traceback)
[Thu Nov 16 18:29:18.573885 2017] [wsgi:error] [pid 12647:tid 140022633289472]   File "/usr/local/lib/python3.5/dist-packages/django/utils/six.py", line 685, in reraise
[Thu Nov 16 18:29:18.573891 2017] [wsgi:error] [pid 12647:tid 140022633289472]     raise value.with_traceback(tb)
[Thu Nov 16 18:29:18.573898 2017] [wsgi:error] [pid 12647:tid 140022633289472]   File "/usr/local/lib/python3.5/dist-packages/django/db/backends/utils.py", line 64, in execute
[Thu Nov 16 18:29:18.573902 2017] [wsgi:error] [pid 12647:tid 140022633289472]     return self.cursor.execute(sql, params)
[Thu Nov 16 18:29:18.573909 2017] [wsgi:error] [pid 12647:tid 140022633289472]   File "/usr/local/lib/python3.5/dist-packages/django/db/backends/sqlite3/base.py", line 337, in execute
[Thu Nov 16 18:29:18.573912 2017] [wsgi:error] [pid 12647:tid 140022633289472]     return Database.Cursor.execute(self, query, params)
[Thu Nov 16 18:29:18.573918 2017] [wsgi:error] [pid 12647:tid 140022633289472] django.db.utils.OperationalError: unable to open database file
[Thu Nov 16 18:29:18.573928 2017] [wsgi:error] [pid 12647:tid 140022633289472] 
[Thu Nov 16 18:29:32.531235 2017] [wsgi:error] [pid 12647:tid 140022750893824] Internal Server Error: /Testline_Details/login/
[Thu Nov 16 18:29:32.531304 2017] [wsgi:error] [pid 12647:tid 140022750893824] Traceback (most recent call last):
[Thu Nov 16 18:29:32.531320 2017] [wsgi:error] [pid 12647:tid 140022750893824]   File "/usr/local/lib/python3.5/dist-packages/django/db/backends/utils.py", line 64, in execute
[Thu Nov 16 18:29:32.531328 2017] [wsgi:error] [pid 12647:tid 140022750893824]     return self.cursor.execute(sql, params)
[Thu Nov 16 18:29:32.531333 2017] [wsgi:error] [pid 12647:tid 140022750893824]   File "/usr/local/lib/python3.5/dist-packages/django/db/backends/sqlite3/base.py", line 337, in execute
[Thu Nov 16 18:29:32.531339 2017] [wsgi:error] [pid 12647:tid 140022750893824]     return Database.Cursor.execute(self, query, params)
[Thu Nov 16 18:29:32.531346 2017] [wsgi:error] [pid 12647:tid 140022750893824] sqlite3.OperationalError: unable to open database file
[Thu Nov 16 18:29:32.531352 2017] [wsgi:error] [pid 12647:tid 140022750893824] 
[Thu Nov 16 18:29:32.531358 2017] [wsgi:error] [pid 12647:tid 140022750893824] The above exception was the direct cause of the following exception:
[Thu Nov 16 18:29:32.531363 2017] [wsgi:error] [pid 12647:tid 140022750893824] 
[Thu Nov 16 18:29:32.531368 2017] [wsgi:error] [pid 12647:tid 140022750893824] Traceback (most recent call last):
[Thu Nov 16 18:29:32.531403 2017] [wsgi:error] [pid 12647:tid 140022750893824]   File "/usr/local/lib/python3.5/dist-packages/django/core/handlers/exception.py", line 39, in inner
[Thu Nov 16 18:29:32.531416 2017] [wsgi:error] [pid 12647:tid 140022750893824]     response = get_response(request)
[Thu Nov 16 18:29:32.531422 2017] [wsgi:error] [pid 12647:tid 140022750893824]   File "/usr/local/lib/python3.5/dist-packages/django/core/handlers/base.py", line 249, in _legacy_get_response
[Thu Nov 16 18:29:32.531429 2017] [wsgi:error] [pid 12647:tid 140022750893824]     response = self._get_response(request)
[Thu Nov 16 18:29:32.531435 2017] [wsgi:error] [pid 12647:tid 140022750893824]   File "/usr/local/lib/python3.5/dist-packages/django/core/handlers/base.py", line 187, in _get_response
[Thu Nov 16 18:29:32.531441 2017] [wsgi:error] [pid 12647:tid 140022750893824]     response = self.process_exception_by_middleware(e, request)
[Thu Nov 16 18:29:32.531449 2017] [wsgi:error] [pid 12647:tid 140022750893824]   File "/usr/local/lib/python3.5/dist-packages/django/core/handlers/base.py", line 185, in _get_response
[Thu Nov 16 18:29:32.531455 2017] [wsgi:error] [pid 12647:tid 140022750893824]     response = wrapped_callback(request, *callback_args, **callback_kwargs)
[Thu Nov 16 18:29:32.531461 2017] [wsgi:error] [pid 12647:tid 140022750893824]   File "/home/sran/Django/SRANTLS/Testline_Details/views.py", line 73, in user_login
[Thu Nov 16 18:29:32.531467 2017] [wsgi:error] [pid 12647:tid 140022750893824]     login(request,user)
[Thu Nov 16 18:29:32.531506 2017] [wsgi:error] [pid 12647:tid 140022750893824]   File "/usr/local/lib/python3.5/dist-packages/django/contrib/auth/__init__.py", line 109, in login
[Thu Nov 16 18:29:32.531517 2017] [wsgi:error] [pid 12647:tid 140022750893824]     request.session.cycle_key()
[Thu Nov 16 18:29:32.531524 2017] [wsgi:error] [pid 12647:tid 140022750893824]   File "/usr/local/lib/python3.5/dist-packages/django/contrib/sessions/backends/base.py", line 311, in cycle_key
[Thu Nov 16 18:29:32.531529 2017] [wsgi:error] [pid 12647:tid 140022750893824]     self.create()
[Thu Nov 16 18:29:32.531533 2017] [wsgi:error] [pid 12647:tid 140022750893824]   File "/usr/local/lib/python3.5/dist-packages/django/contrib/sessions/backends/db.py", line 54, in create
[Thu Nov 16 18:29:32.531538 2017] [wsgi:error] [pid 12647:tid 140022750893824]     self.save(must_create=True)
[Thu Nov 16 18:29:32.531543 2017] [wsgi:error] [pid 12647:tid 140022750893824]   File "/usr/local/lib/python3.5/dist-packages/django/contrib/sessions/backends/db.py", line 87, in save
[Thu Nov 16 18:29:32.531549 2017] [wsgi:error] [pid 12647:tid 140022750893824]     obj.save(force_insert=must_create, force_update=not must_create, using=using)
[Thu Nov 16 18:29:32.531554 2017] [wsgi:error] [pid 12647:tid 140022750893824]   File "/usr/local/lib/python3.5/dist-packages/django/db/models/base.py", line 796, in save
[Thu Nov 16 18:29:32.531560 2017] [wsgi:error] [pid 12647:tid 140022750893824]     force_update=force_update, update_fields=update_fields)
[Thu Nov 16 18:29:32.531565 2017] [wsgi:error] [pid 12647:tid 140022750893824]   File "/usr/local/lib/python3.5/dist-packages/django/db/models/base.py", line 824, in save_base
[Thu Nov 16 18:29:32.531571 2017] [wsgi:error] [pid 12647:tid 140022750893824]     updated = self._save_table(raw, cls, force_insert, force_update, using, update_fields)
[Thu Nov 16 18:29:32.531576 2017] [wsgi:error] [pid 12647:tid 140022750893824]   File "/usr/local/lib/python3.5/dist-packages/django/db/models/base.py", line 908, in _save_table
[Thu Nov 16 18:29:32.531581 2017] [wsgi:error] [pid 12647:tid 140022750893824]     result = self._do_insert(cls._base_manager, using, fields, update_pk, raw)
[Thu Nov 16 18:29:32.531587 2017] [wsgi:error] [pid 12647:tid 140022750893824]   File "/usr/local/lib/python3.5/dist-packages/django/db/models/base.py", line 947, in _do_insert
[Thu Nov 16 18:29:32.531592 2017] [wsgi:error] [pid 12647:tid 140022750893824]     using=using, raw=raw)
[Thu Nov 16 18:29:32.531596 2017] [wsgi:error] [pid 12647:tid 140022750893824]   File "/usr/local/lib/python3.5/dist-packages/django/db/models/manager.py", line 85, in manager_method
[Thu Nov 16 18:29:32.531602 2017] [wsgi:error] [pid 12647:tid 140022750893824]     return getattr(self.get_queryset(), name)(*args, **kwargs)
[Thu Nov 16 18:29:32.531607 2017] [wsgi:error] [pid 12647:tid 140022750893824]   File "/usr/local/lib/python3.5/dist-packages/django/db/models/query.py", line 1045, in _insert
[Thu Nov 16 18:29:32.531612 2017] [wsgi:error] [pid 12647:tid 140022750893824]     return query.get_compiler(using=using).execute_sql(return_id)
[Thu Nov 16 18:29:32.531618 2017] [wsgi:error] [pid 12647:tid 140022750893824]   File "/usr/local/lib/python3.5/dist-packages/django/db/models/sql/compiler.py", line 1054, in execute_sql
[Thu Nov 16 18:29:32.531623 2017] [wsgi:error] [pid 12647:tid 140022750893824]     cursor.execute(sql, params)
[Thu Nov 16 18:29:32.531628 2017] [wsgi:error] [pid 12647:tid 140022750893824]   File "/usr/local/lib/python3.5/dist-packages/django/db/backends/utils.py", line 79, in execute
[Thu Nov 16 18:29:32.531632 2017] [wsgi:error] [pid 12647:tid 140022750893824]     return super(CursorDebugWrapper, self).execute(sql, params)
[Thu Nov 16 18:29:32.531638 2017] [wsgi:error] [pid 12647:tid 140022750893824]   File "/usr/local/lib/python3.5/dist-packages/django/db/backends/utils.py", line 64, in execute
[Thu Nov 16 18:29:32.531647 2017] [wsgi:error] [pid 12647:tid 140022750893824]     return self.cursor.execute(sql, params)
[Thu Nov 16 18:29:32.531658 2017] [wsgi:error] [pid 12647:tid 140022750893824]   File "/usr/local/lib/python3.5/dist-packages/django/db/utils.py", line 94, in __exit__
[Thu Nov 16 18:29:32.531664 2017] [wsgi:error] [pid 12647:tid 140022750893824]     six.reraise(dj_exc_type, dj_exc_value, traceback)
[Thu Nov 16 18:29:32.531669 2017] [wsgi:error] [pid 12647:tid 140022750893824]   File "/usr/local/lib/python3.5/dist-packages/django/utils/six.py", line 685, in reraise
[Thu Nov 16 18:29:32.531673 2017] [wsgi:error] [pid 12647:tid 140022750893824]     raise value.with_traceback(tb)
[Thu Nov 16 18:29:32.531682 2017] [wsgi:error] [pid 12647:tid 140022750893824]   File "/usr/local/lib/python3.5/dist-packages/django/db/backends/utils.py", line 64, in execute
[Thu Nov 16 18:29:32.531688 2017] [wsgi:error] [pid 12647:tid 140022750893824]     return self.cursor.execute(sql, params)
[Thu Nov 16 18:29:32.531694 2017] [wsgi:error] [pid 12647:tid 140022750893824]   File "/usr/local/lib/python3.5/dist-packages/django/db/backends/sqlite3/base.py", line 337, in execute
[Thu Nov 16 18:29:32.531700 2017] [wsgi:error] [pid 12647:tid 140022750893824]     return Database.Cursor.execute(self, query, params)
[Thu Nov 16 18:29:32.531710 2017] [wsgi:error] [pid 12647:tid 140022750893824] django.db.utils.OperationalError: unable to open database file
[Thu Nov 16 18:29:32.531723 2017] [wsgi:error] [pid 12647:tid 140022750893824] 
[Thu Nov 16 18:38:46.777116 2017] [wsgi:error] [pid 1025:tid 139851899975424] Not Found: /favicon.ico
[Thu Nov 16 21:17:06.986917 2017] [wsgi:error] [pid 5361:tid 140559129847552] Not Found: /favicon.ico
[Thu Nov 16 21:17:23.543712 2017] [wsgi:error] [pid 5361:tid 140559129847552] Not Found: /favicon.ico
[Thu Nov 16 21:17:29.723841 2017] [wsgi:error] [pid 5361:tid 140559129847552] Internal Server Error: /Testline_Details/login/
[Thu Nov 16 21:17:29.723897 2017] [wsgi:error] [pid 5361:tid 140559129847552] Traceback (most recent call last):
[Thu Nov 16 21:17:29.723902 2017] [wsgi:error] [pid 5361:tid 140559129847552]   File "/usr/local/lib/python3.5/dist-packages/django/db/backends/utils.py", line 64, in execute
[Thu Nov 16 21:17:29.723909 2017] [wsgi:error] [pid 5361:tid 140559129847552]     return self.cursor.execute(sql, params)
[Thu Nov 16 21:17:29.723913 2017] [wsgi:error] [pid 5361:tid 140559129847552]   File "/usr/local/lib/python3.5/dist-packages/django/db/backends/sqlite3/base.py", line 337, in execute
[Thu Nov 16 21:17:29.723917 2017] [wsgi:error] [pid 5361:tid 140559129847552]     return Database.Cursor.execute(self, query, params)
[Thu Nov 16 21:17:29.723921 2017] [wsgi:error] [pid 5361:tid 140559129847552] sqlite3.OperationalError: attempt to write a readonly database
[Thu Nov 16 21:17:29.723925 2017] [wsgi:error] [pid 5361:tid 140559129847552] 
[Thu Nov 16 21:17:29.723928 2017] [wsgi:error] [pid 5361:tid 140559129847552] The above exception was the direct cause of the following exception:
[Thu Nov 16 21:17:29.723932 2017] [wsgi:error] [pid 5361:tid 140559129847552] 
[Thu Nov 16 21:17:29.723936 2017] [wsgi:error] [pid 5361:tid 140559129847552] Traceback (most recent call last):
[Thu Nov 16 21:17:29.723939 2017] [wsgi:error] [pid 5361:tid 140559129847552]   File "/usr/local/lib/python3.5/dist-packages/django/core/handlers/exception.py", line 39, in inner
[Thu Nov 16 21:17:29.723943 2017] [wsgi:error] [pid 5361:tid 140559129847552]     response = get_response(request)
[Thu Nov 16 21:17:29.723947 2017] [wsgi:error] [pid 5361:tid 140559129847552]   File "/usr/local/lib/python3.5/dist-packages/django/core/handlers/base.py", line 249, in _legacy_get_response
[Thu Nov 16 21:17:29.723951 2017] [wsgi:error] [pid 5361:tid 140559129847552]     response = self._get_response(request)
[Thu Nov 16 21:17:29.723954 2017] [wsgi:error] [pid 5361:tid 140559129847552]   File "/usr/local/lib/python3.5/dist-packages/django/core/handlers/base.py", line 187, in _get_response
[Thu Nov 16 21:17:29.723960 2017] [wsgi:error] [pid 5361:tid 140559129847552]     response = self.process_exception_by_middleware(e, request)
[Thu Nov 16 21:17:29.723979 2017] [wsgi:error] [pid 5361:tid 140559129847552]   File "/usr/local/lib/python3.5/dist-packages/django/core/handlers/base.py", line 185, in _get_response
[Thu Nov 16 21:17:29.723986 2017] [wsgi:error] [pid 5361:tid 140559129847552]     response = wrapped_callback(request, *callback_args, **callback_kwargs)
[Thu Nov 16 21:17:29.723991 2017] [wsgi:error] [pid 5361:tid 140559129847552]   File "/home/sran/Django/SRANTLS/Testline_Details/views.py", line 73, in user_login
[Thu Nov 16 21:17:29.723996 2017] [wsgi:error] [pid 5361:tid 140559129847552]     login(request,user)
[Thu Nov 16 21:17:29.724000 2017] [wsgi:error] [pid 5361:tid 140559129847552]   File "/usr/local/lib/python3.5/dist-packages/django/contrib/auth/__init__.py", line 109, in login
[Thu Nov 16 21:17:29.724005 2017] [wsgi:error] [pid 5361:tid 140559129847552]     request.session.cycle_key()
[Thu Nov 16 21:17:29.724010 2017] [wsgi:error] [pid 5361:tid 140559129847552]   File "/usr/local/lib/python3.5/dist-packages/django/contrib/sessions/backends/base.py", line 311, in cycle_key
[Thu Nov 16 21:17:29.724015 2017] [wsgi:error] [pid 5361:tid 140559129847552]     self.create()
[Thu Nov 16 21:17:29.724019 2017] [wsgi:error] [pid 5361:tid 140559129847552]   File "/usr/local/lib/python3.5/dist-packages/django/contrib/sessions/backends/db.py", line 54, in create
[Thu Nov 16 21:17:29.724024 2017] [wsgi:error] [pid 5361:tid 140559129847552]     self.save(must_create=True)
[Thu Nov 16 21:17:29.724033 2017] [wsgi:error] [pid 5361:tid 140559129847552]   File "/usr/local/lib/python3.5/dist-packages/django/contrib/sessions/backends/db.py", line 87, in save
[Thu Nov 16 21:17:29.724040 2017] [wsgi:error] [pid 5361:tid 140559129847552]     obj.save(force_insert=must_create, force_update=not must_create, using=using)
[Thu Nov 16 21:17:29.724044 2017] [wsgi:error] [pid 5361:tid 140559129847552]   File "/usr/local/lib/python3.5/dist-packages/django/db/models/base.py", line 796, in save
[Thu Nov 16 21:17:29.724049 2017] [wsgi:error] [pid 5361:tid 140559129847552]     force_update=force_update, update_fields=update_fields)
[Thu Nov 16 21:17:29.724054 2017] [wsgi:error] [pid 5361:tid 140559129847552]   File "/usr/local/lib/python3.5/dist-packages/django/db/models/base.py", line 824, in save_base
[Thu Nov 16 21:17:29.724059 2017] [wsgi:error] [pid 5361:tid 140559129847552]     updated = self._save_table(raw, cls, force_insert, force_update, using, update_fields)
[Thu Nov 16 21:17:29.724064 2017] [wsgi:error] [pid 5361:tid 140559129847552]   File "/usr/local/lib/python3.5/dist-packages/django/db/models/base.py", line 908, in _save_table
[Thu Nov 16 21:17:29.724069 2017] [wsgi:error] [pid 5361:tid 140559129847552]     result = self._do_insert(cls._base_manager, using, fields, update_pk, raw)
[Thu Nov 16 21:17:29.724073 2017] [wsgi:error] [pid 5361:tid 140559129847552]   File "/usr/local/lib/python3.5/dist-packages/django/db/models/base.py", line 947, in _do_insert
[Thu Nov 16 21:17:29.724077 2017] [wsgi:error] [pid 5361:tid 140559129847552]     using=using, raw=raw)
[Thu Nov 16 21:17:29.724082 2017] [wsgi:error] [pid 5361:tid 140559129847552]   File "/usr/local/lib/python3.5/dist-packages/django/db/models/manager.py", line 85, in manager_method
[Thu Nov 16 21:17:29.724087 2017] [wsgi:error] [pid 5361:tid 140559129847552]     return getattr(self.get_queryset(), name)(*args, **kwargs)
[Thu Nov 16 21:17:29.724092 2017] [wsgi:error] [pid 5361:tid 140559129847552]   File "/usr/local/lib/python3.5/dist-packages/django/db/models/query.py", line 1045, in _insert
[Thu Nov 16 21:17:29.724096 2017] [wsgi:error] [pid 5361:tid 140559129847552]     return query.get_compiler(using=using).execute_sql(return_id)
[Thu Nov 16 21:17:29.724100 2017] [wsgi:error] [pid 5361:tid 140559129847552]   File "/usr/local/lib/python3.5/dist-packages/django/db/models/sql/compiler.py", line 1054, in execute_sql
[Thu Nov 16 21:17:29.724105 2017] [wsgi:error] [pid 5361:tid 140559129847552]     cursor.execute(sql, params)
[Thu Nov 16 21:17:29.724110 2017] [wsgi:error] [pid 5361:tid 140559129847552]   File "/usr/local/lib/python3.5/dist-packages/django/db/backends/utils.py", line 79, in execute
[Thu Nov 16 21:17:29.724119 2017] [wsgi:error] [pid 5361:tid 140559129847552]     return super(CursorDebugWrapper, self).execute(sql, params)
[Thu Nov 16 21:17:29.724125 2017] [wsgi:error] [pid 5361:tid 140559129847552]   File "/usr/local/lib/python3.5/dist-packages/django/db/backends/utils.py", line 64, in execute
[Thu Nov 16 21:17:29.724130 2017] [wsgi:error] [pid 5361:tid 140559129847552]     return self.cursor.execute(sql, params)
[Thu Nov 16 21:17:29.724136 2017] [wsgi:error] [pid 5361:tid 140559129847552]   File "/usr/local/lib/python3.5/dist-packages/django/db/utils.py", line 94, in __exit__
[Thu Nov 16 21:17:29.724140 2017] [wsgi:error] [pid 5361:tid 140559129847552]     six.reraise(dj_exc_type, dj_exc_value, traceback)
[Thu Nov 16 21:17:29.724143 2017] [wsgi:error] [pid 5361:tid 140559129847552]   File "/usr/local/lib/python3.5/dist-packages/django/utils/six.py", line 685, in reraise
[Thu Nov 16 21:17:29.724146 2017] [wsgi:error] [pid 5361:tid 140559129847552]     raise value.with_traceback(tb)
[Thu Nov 16 21:17:29.724149 2017] [wsgi:error] [pid 5361:tid 140559129847552]   File "/usr/local/lib/python3.5/dist-packages/django/db/backends/utils.py", line 64, in execute
[Thu Nov 16 21:17:29.724153 2017] [wsgi:error] [pid 5361:tid 140559129847552]     return self.cursor.execute(sql, params)
[Thu Nov 16 21:17:29.724156 2017] [wsgi:error] [pid 5361:tid 140559129847552]   File "/usr/local/lib/python3.5/dist-packages/django/db/backends/sqlite3/base.py", line 337, in execute
[Thu Nov 16 21:17:29.724159 2017] [wsgi:error] [pid 5361:tid 140559129847552]     return Database.Cursor.execute(self, query, params)
[Thu Nov 16 21:17:29.724165 2017] [wsgi:error] [pid 5361:tid 140559129847552] django.db.utils.OperationalError: attempt to write a readonly database
[Thu Nov 16 21:17:29.724175 2017] [wsgi:error] [pid 5361:tid 140559129847552] 
[Thu Nov 16 21:28:31.614372 2017] [core:error] [pid 15345:tid 140570573051648] (13)Permission denied: [client 192.168.1.9:50393] AH00035: access to /Testline_Details/login/ denied (filesystem path '/home/sran/Django/SRANTLS/SRANTLS') because search permissions are missing on a component of the path, referer: http://192.168.1.3/Testline_Details/
[Thu Nov 16 21:28:37.677078 2017] [core:error] [pid 15346:tid 140570573051648] (13)Permission denied: [client 192.168.1.9:50397] AH00035: access to /Testline_Details/ denied (filesystem path '/home/sran/Django/SRANTLS/SRANTLS') because search permissions are missing on a component of the path
[Thu Nov 16 21:28:45.895681 2017] [core:error] [pid 15345:tid 140570564658944] (13)Permission denied: [client 192.168.1.9:50398] AH00035: access to / denied (filesystem path '/home/sran/Django/SRANTLS/SRANTLS') because search permissions are missing on a component of the path
[Thu Nov 16 21:28:52.389815 2017] [core:error] [pid 15345:tid 140570556266240] (13)Permission denied: [client 192.168.1.9:50403] AH00035: access to / denied (filesystem path '/home/sran/Django/SRANTLS/SRANTLS') because search permissions are missing on a component of the path
[Thu Nov 16 21:29:11.217139 2017] [core:error] [pid 15346:tid 140570556266240] (13)Permission denied: [client 192.168.1.3:44568] AH00035: access to /Testline_Details/ denied (filesystem path '/home/sran/Django/SRANTLS/SRANTLS') because search permissions are missing on a component of the path, referer: http://192.168.1.3/Testline_Details/
[Thu Nov 16 21:29:19.696108 2017] [core:error] [pid 15345:tid 140570547873536] (13)Permission denied: [client 192.168.1.3:44570] AH00035: access to /Testline_Details/ denied (filesystem path '/home/sran/Django/SRANTLS/SRANTLS') because search permissions are missing on a component of the path
[Thu Nov 16 21:29:22.741829 2017] [core:error] [pid 15345:tid 140570539480832] (13)Permission denied: [client 192.168.1.3:44570] AH00035: access to /Testline_Details/ denied (filesystem path '/home/sran/Django/SRANTLS/SRANTLS') because search permissions are missing on a component of the path
[Thu Nov 16 21:29:24.431497 2017] [core:error] [pid 15345:tid 140570531079936] (13)Permission denied: [client 192.168.1.3:44570] AH00035: access to /Testline_Details/ denied (filesystem path '/home/sran/Django/SRANTLS/SRANTLS') because search permissions are missing on a component of the path
[Thu Nov 16 21:36:11.067133 2017] [wsgi:error] [pid 15344:tid 140570564658944] Internal Server Error: /Testline_Details/login/
[Thu Nov 16 21:36:11.067197 2017] [wsgi:error] [pid 15344:tid 140570564658944] Traceback (most recent call last):
[Thu Nov 16 21:36:11.067204 2017] [wsgi:error] [pid 15344:tid 140570564658944]   File "/usr/local/lib/python3.5/dist-packages/django/db/backends/utils.py", line 64, in execute
[Thu Nov 16 21:36:11.067211 2017] [wsgi:error] [pid 15344:tid 140570564658944]     return self.cursor.execute(sql, params)
[Thu Nov 16 21:36:11.067215 2017] [wsgi:error] [pid 15344:tid 140570564658944]   File "/usr/local/lib/python3.5/dist-packages/django/db/backends/sqlite3/base.py", line 337, in execute
[Thu Nov 16 21:36:11.067220 2017] [wsgi:error] [pid 15344:tid 140570564658944]     return Database.Cursor.execute(self, query, params)
[Thu Nov 16 21:36:11.067225 2017] [wsgi:error] [pid 15344:tid 140570564658944] sqlite3.OperationalError: attempt to write a readonly database
[Thu Nov 16 21:36:11.067229 2017] [wsgi:error] [pid 15344:tid 140570564658944] 
[Thu Nov 16 21:36:11.067234 2017] [wsgi:error] [pid 15344:tid 140570564658944] The above exception was the direct cause of the following exception:
[Thu Nov 16 21:36:11.067238 2017] [wsgi:error] [pid 15344:tid 140570564658944] 
[Thu Nov 16 21:36:11.067242 2017] [wsgi:error] [pid 15344:tid 140570564658944] Traceback (most recent call last):
[Thu Nov 16 21:36:11.067247 2017] [wsgi:error] [pid 15344:tid 140570564658944]   File "/usr/local/lib/python3.5/dist-packages/django/core/handlers/exception.py", line 39, in inner
[Thu Nov 16 21:36:11.067251 2017] [wsgi:error] [pid 15344:tid 140570564658944]     response = get_response(request)
[Thu Nov 16 21:36:11.067255 2017] [wsgi:error] [pid 15344:tid 140570564658944]   File "/usr/local/lib/python3.5/dist-packages/django/core/handlers/base.py", line 249, in _legacy_get_response
[Thu Nov 16 21:36:11.067261 2017] [wsgi:error] [pid 15344:tid 140570564658944]     response = self._get_response(request)
[Thu Nov 16 21:36:11.067265 2017] [wsgi:error] [pid 15344:tid 140570564658944]   File "/usr/local/lib/python3.5/dist-packages/django/core/handlers/base.py", line 187, in _get_response
[Thu Nov 16 21:36:11.067271 2017] [wsgi:error] [pid 15344:tid 140570564658944]     response = self.process_exception_by_middleware(e, request)
[Thu Nov 16 21:36:11.067276 2017] [wsgi:error] [pid 15344:tid 140570564658944]   File "/usr/local/lib/python3.5/dist-packages/django/core/handlers/base.py", line 185, in _get_response
[Thu Nov 16 21:36:11.067285 2017] [wsgi:error] [pid 15344:tid 140570564658944]     response = wrapped_callback(request, *callback_args, **callback_kwargs)
[Thu Nov 16 21:36:11.067291 2017] [wsgi:error] [pid 15344:tid 140570564658944]   File "/home/sran/Django/SRANTLS/Testline_Details/views.py", line 73, in user_login
[Thu Nov 16 21:36:11.067297 2017] [wsgi:error] [pid 15344:tid 140570564658944]     login(request,user)
[Thu Nov 16 21:36:11.067303 2017] [wsgi:error] [pid 15344:tid 140570564658944]   File "/usr/local/lib/python3.5/dist-packages/django/contrib/auth/__init__.py", line 109, in login
[Thu Nov 16 21:36:11.067310 2017] [wsgi:error] [pid 15344:tid 140570564658944]     request.session.cycle_key()
[Thu Nov 16 21:36:11.067314 2017] [wsgi:error] [pid 15344:tid 140570564658944]   File "/usr/local/lib/python3.5/dist-packages/django/contrib/sessions/backends/base.py", line 311, in cycle_key
[Thu Nov 16 21:36:11.067318 2017] [wsgi:error] [pid 15344:tid 140570564658944]     self.create()
[Thu Nov 16 21:36:11.067322 2017] [wsgi:error] [pid 15344:tid 140570564658944]   File "/usr/local/lib/python3.5/dist-packages/django/contrib/sessions/backends/db.py", line 54, in create
[Thu Nov 16 21:36:11.067325 2017] [wsgi:error] [pid 15344:tid 140570564658944]     self.save(must_create=True)
[Thu Nov 16 21:36:11.067342 2017] [wsgi:error] [pid 15344:tid 140570564658944]   File "/usr/local/lib/python3.5/dist-packages/django/contrib/sessions/backends/db.py", line 87, in save
[Thu Nov 16 21:36:11.067346 2017] [wsgi:error] [pid 15344:tid 140570564658944]     obj.save(force_insert=must_create, force_update=not must_create, using=using)
[Thu Nov 16 21:36:11.067349 2017] [wsgi:error] [pid 15344:tid 140570564658944]   File "/usr/local/lib/python3.5/dist-packages/django/db/models/base.py", line 796, in save
[Thu Nov 16 21:36:11.067353 2017] [wsgi:error] [pid 15344:tid 140570564658944]     force_update=force_update, update_fields=update_fields)
[Thu Nov 16 21:36:11.067356 2017] [wsgi:error] [pid 15344:tid 140570564658944]   File "/usr/local/lib/python3.5/dist-packages/django/db/models/base.py", line 824, in save_base
[Thu Nov 16 21:36:11.067360 2017] [wsgi:error] [pid 15344:tid 140570564658944]     updated = self._save_table(raw, cls, force_insert, force_update, using, update_fields)
[Thu Nov 16 21:36:11.067363 2017] [wsgi:error] [pid 15344:tid 140570564658944]   File "/usr/local/lib/python3.5/dist-packages/django/db/models/base.py", line 908, in _save_table
[Thu Nov 16 21:36:11.067367 2017] [wsgi:error] [pid 15344:tid 140570564658944]     result = self._do_insert(cls._base_manager, using, fields, update_pk, raw)
[Thu Nov 16 21:36:11.067370 2017] [wsgi:error] [pid 15344:tid 140570564658944]   File "/usr/local/lib/python3.5/dist-packages/django/db/models/base.py", line 947, in _do_insert
[Thu Nov 16 21:36:11.067373 2017] [wsgi:error] [pid 15344:tid 140570564658944]     using=using, raw=raw)
[Thu Nov 16 21:36:11.067377 2017] [wsgi:error] [pid 15344:tid 140570564658944]   File "/usr/local/lib/python3.5/dist-packages/django/db/models/manager.py", line 85, in manager_method
[Thu Nov 16 21:36:11.067380 2017] [wsgi:error] [pid 15344:tid 140570564658944]     return getattr(self.get_queryset(), name)(*args, **kwargs)
[Thu Nov 16 21:36:11.067383 2017] [wsgi:error] [pid 15344:tid 140570564658944]   File "/usr/local/lib/python3.5/dist-packages/django/db/models/query.py", line 1045, in _insert
[Thu Nov 16 21:36:11.067387 2017] [wsgi:error] [pid 15344:tid 140570564658944]     return query.get_compiler(using=using).execute_sql(return_id)
[Thu Nov 16 21:36:11.067390 2017] [wsgi:error] [pid 15344:tid 140570564658944]   File "/usr/local/lib/python3.5/dist-packages/django/db/models/sql/compiler.py", line 1054, in execute_sql
[Thu Nov 16 21:36:11.067394 2017] [wsgi:error] [pid 15344:tid 140570564658944]     cursor.execute(sql, params)
[Thu Nov 16 21:36:11.067397 2017] [wsgi:error] [pid 15344:tid 140570564658944]   File "/usr/local/lib/python3.5/dist-packages/django/db/backends/utils.py", line 79, in execute
[Thu Nov 16 21:36:11.067400 2017] [wsgi:error] [pid 15344:tid 140570564658944]     return super(CursorDebugWrapper, self).execute(sql, params)
[Thu Nov 16 21:36:11.067404 2017] [wsgi:error] [pid 15344:tid 140570564658944]   File "/usr/local/lib/python3.5/dist-packages/django/db/backends/utils.py", line 64, in execute
[Thu Nov 16 21:36:11.067407 2017] [wsgi:error] [pid 15344:tid 140570564658944]     return self.cursor.execute(sql, params)
[Thu Nov 16 21:36:11.067411 2017] [wsgi:error] [pid 15344:tid 140570564658944]   File "/usr/local/lib/python3.5/dist-packages/django/db/utils.py", line 94, in __exit__
[Thu Nov 16 21:36:11.067414 2017] [wsgi:error] [pid 15344:tid 140570564658944]     six.reraise(dj_exc_type, dj_exc_value, traceback)
[Thu Nov 16 21:36:11.067417 2017] [wsgi:error] [pid 15344:tid 140570564658944]   File "/usr/local/lib/python3.5/dist-packages/django/utils/six.py", line 685, in reraise
[Thu Nov 16 21:36:11.067421 2017] [wsgi:error] [pid 15344:tid 140570564658944]     raise value.with_traceback(tb)
[Thu Nov 16 21:36:11.067424 2017] [wsgi:error] [pid 15344:tid 140570564658944]   File "/usr/local/lib/python3.5/dist-packages/django/db/backends/utils.py", line 64, in execute
[Thu Nov 16 21:36:11.067427 2017] [wsgi:error] [pid 15344:tid 140570564658944]     return self.cursor.execute(sql, params)
[Thu Nov 16 21:36:11.067434 2017] [wsgi:error] [pid 15344:tid 140570564658944]   File "/usr/local/lib/python3.5/dist-packages/django/db/backends/sqlite3/base.py", line 337, in execute
[Thu Nov 16 21:36:11.067438 2017] [wsgi:error] [pid 15344:tid 140570564658944]     return Database.Cursor.execute(self, query, params)
[Thu Nov 16 21:36:11.067448 2017] [wsgi:error] [pid 15344:tid 140570564658944] django.db.utils.OperationalError: attempt to write a readonly database
[Thu Nov 16 21:36:11.067459 2017] [wsgi:error] [pid 15344:tid 140570564658944] 
[Thu Nov 16 21:40:57.180655 2017] [wsgi:error] [pid 15344:tid 140570447054592] Internal Server Error: /Testline_Details/login/
[Thu Nov 16 21:40:57.180715 2017] [wsgi:error] [pid 15344:tid 140570447054592] Traceback (most recent call last):
[Thu Nov 16 21:40:57.180720 2017] [wsgi:error] [pid 15344:tid 140570447054592]   File "/usr/local/lib/python3.5/dist-packages/django/db/backends/utils.py", line 64, in execute
[Thu Nov 16 21:40:57.180723 2017] [wsgi:error] [pid 15344:tid 140570447054592]     return self.cursor.execute(sql, params)
[Thu Nov 16 21:40:57.180731 2017] [wsgi:error] [pid 15344:tid 140570447054592]   File "/usr/local/lib/python3.5/dist-packages/django/db/backends/sqlite3/base.py", line 337, in execute
[Thu Nov 16 21:40:57.180734 2017] [wsgi:error] [pid 15344:tid 140570447054592]     return Database.Cursor.execute(self, query, params)
[Thu Nov 16 21:40:57.180738 2017] [wsgi:error] [pid 15344:tid 140570447054592] sqlite3.OperationalError: attempt to write a readonly database
[Thu Nov 16 21:40:57.180742 2017] [wsgi:error] [pid 15344:tid 140570447054592] 
[Thu Nov 16 21:40:57.180746 2017] [wsgi:error] [pid 15344:tid 140570447054592] The above exception was the direct cause of the following exception:
[Thu Nov 16 21:40:57.180749 2017] [wsgi:error] [pid 15344:tid 140570447054592] 
[Thu Nov 16 21:40:57.180753 2017] [wsgi:error] [pid 15344:tid 140570447054592] Traceback (most recent call last):
[Thu Nov 16 21:40:57.180756 2017] [wsgi:error] [pid 15344:tid 140570447054592]   File "/usr/local/lib/python3.5/dist-packages/django/core/handlers/exception.py", line 39, in inner
[Thu Nov 16 21:40:57.180760 2017] [wsgi:error] [pid 15344:tid 140570447054592]     response = get_response(request)
[Thu Nov 16 21:40:57.180763 2017] [wsgi:error] [pid 15344:tid 140570447054592]   File "/usr/local/lib/python3.5/dist-packages/django/core/handlers/base.py", line 249, in _legacy_get_response
[Thu Nov 16 21:40:57.180767 2017] [wsgi:error] [pid 15344:tid 140570447054592]     response = self._get_response(request)
[Thu Nov 16 21:40:57.180770 2017] [wsgi:error] [pid 15344:tid 140570447054592]   File "/usr/local/lib/python3.5/dist-packages/django/core/handlers/base.py", line 187, in _get_response
[Thu Nov 16 21:40:57.180774 2017] [wsgi:error] [pid 15344:tid 140570447054592]     response = self.process_exception_by_middleware(e, request)
[Thu Nov 16 21:40:57.180778 2017] [wsgi:error] [pid 15344:tid 140570447054592]   File "/usr/local/lib/python3.5/dist-packages/django/core/handlers/base.py", line 185, in _get_response
[Thu Nov 16 21:40:57.180782 2017] [wsgi:error] [pid 15344:tid 140570447054592]     response = wrapped_callback(request, *callback_args, **callback_kwargs)
[Thu Nov 16 21:40:57.180785 2017] [wsgi:error] [pid 15344:tid 140570447054592]   File "/home/sran/Django/SRANTLS/Testline_Details/views.py", line 73, in user_login
[Thu Nov 16 21:40:57.180789 2017] [wsgi:error] [pid 15344:tid 140570447054592]     login(request,user)
[Thu Nov 16 21:40:57.180792 2017] [wsgi:error] [pid 15344:tid 140570447054592]   File "/usr/local/lib/python3.5/dist-packages/django/contrib/auth/__init__.py", line 109, in login
[Thu Nov 16 21:40:57.180796 2017] [wsgi:error] [pid 15344:tid 140570447054592]     request.session.cycle_key()
[Thu Nov 16 21:40:57.180799 2017] [wsgi:error] [pid 15344:tid 140570447054592]   File "/usr/local/lib/python3.5/dist-packages/django/contrib/sessions/backends/base.py", line 311, in cycle_key
[Thu Nov 16 21:40:57.180803 2017] [wsgi:error] [pid 15344:tid 140570447054592]     self.create()
[Thu Nov 16 21:40:57.180819 2017] [wsgi:error] [pid 15344:tid 140570447054592]   File "/usr/local/lib/python3.5/dist-packages/django/contrib/sessions/backends/db.py", line 54, in create
[Thu Nov 16 21:40:57.180823 2017] [wsgi:error] [pid 15344:tid 140570447054592]     self.save(must_create=True)
[Thu Nov 16 21:40:57.180827 2017] [wsgi:error] [pid 15344:tid 140570447054592]   File "/usr/local/lib/python3.5/dist-packages/django/contrib/sessions/backends/db.py", line 87, in save
[Thu Nov 16 21:40:57.180830 2017] [wsgi:error] [pid 15344:tid 140570447054592]     obj.save(force_insert=must_create, force_update=not must_create, using=using)
[Thu Nov 16 21:40:57.180834 2017] [wsgi:error] [pid 15344:tid 140570447054592]   File "/usr/local/lib/python3.5/dist-packages/django/db/models/base.py", line 796, in save
[Thu Nov 16 21:40:57.180837 2017] [wsgi:error] [pid 15344:tid 140570447054592]     force_update=force_update, update_fields=update_fields)
[Thu Nov 16 21:40:57.180841 2017] [wsgi:error] [pid 15344:tid 140570447054592]   File "/usr/local/lib/python3.5/dist-packages/django/db/models/base.py", line 824, in save_base
[Thu Nov 16 21:40:57.180844 2017] [wsgi:error] [pid 15344:tid 140570447054592]     updated = self._save_table(raw, cls, force_insert, force_update, using, update_fields)
[Thu Nov 16 21:40:57.180848 2017] [wsgi:error] [pid 15344:tid 140570447054592]   File "/usr/local/lib/python3.5/dist-packages/django/db/models/base.py", line 908, in _save_table
[Thu Nov 16 21:40:57.180851 2017] [wsgi:error] [pid 15344:tid 140570447054592]     result = self._do_insert(cls._base_manager, using, fields, update_pk, raw)
[Thu Nov 16 21:40:57.180855 2017] [wsgi:error] [pid 15344:tid 140570447054592]   File "/usr/local/lib/python3.5/dist-packages/django/db/models/base.py", line 947, in _do_insert
[Thu Nov 16 21:40:57.180858 2017] [wsgi:error] [pid 15344:tid 140570447054592]     using=using, raw=raw)
[Thu Nov 16 21:40:57.180862 2017] [wsgi:error] [pid 15344:tid 140570447054592]   File "/usr/local/lib/python3.5/dist-packages/django/db/models/manager.py", line 85, in manager_method
[Thu Nov 16 21:40:57.180865 2017] [wsgi:error] [pid 15344:tid 140570447054592]     return getattr(self.get_queryset(), name)(*args, **kwargs)
[Thu Nov 16 21:40:57.180869 2017] [wsgi:error] [pid 15344:tid 140570447054592]   File "/usr/local/lib/python3.5/dist-packages/django/db/models/query.py", line 1045, in _insert
[Thu Nov 16 21:40:57.180872 2017] [wsgi:error] [pid 15344:tid 140570447054592]     return query.get_compiler(using=using).execute_sql(return_id)
[Thu Nov 16 21:40:57.180876 2017] [wsgi:error] [pid 15344:tid 140570447054592]   File "/usr/local/lib/python3.5/dist-packages/django/db/models/sql/compiler.py", line 1054, in execute_sql
[Thu Nov 16 21:40:57.180879 2017] [wsgi:error] [pid 15344:tid 140570447054592]     cursor.execute(sql, params)
[Thu Nov 16 21:40:57.180882 2017] [wsgi:error] [pid 15344:tid 140570447054592]   File "/usr/local/lib/python3.5/dist-packages/django/db/backends/utils.py", line 79, in execute
[Thu Nov 16 21:40:57.180886 2017] [wsgi:error] [pid 15344:tid 140570447054592]     return super(CursorDebugWrapper, self).execute(sql, params)
[Thu Nov 16 21:40:57.180889 2017] [wsgi:error] [pid 15344:tid 140570447054592]   File "/usr/local/lib/python3.5/dist-packages/django/db/backends/utils.py", line 64, in execute
[Thu Nov 16 21:40:57.180893 2017] [wsgi:error] [pid 15344:tid 140570447054592]     return self.cursor.execute(sql, params)
[Thu Nov 16 21:40:57.180896 2017] [wsgi:error] [pid 15344:tid 140570447054592]   File "/usr/local/lib/python3.5/dist-packages/django/db/utils.py", line 94, in __exit__
[Thu Nov 16 21:40:57.180900 2017] [wsgi:error] [pid 15344:tid 140570447054592]     six.reraise(dj_exc_type, dj_exc_value, traceback)
[Thu Nov 16 21:40:57.180903 2017] [wsgi:error] [pid 15344:tid 140570447054592]   File "/usr/local/lib/python3.5/dist-packages/django/utils/six.py", line 685, in reraise
[Thu Nov 16 21:40:57.180907 2017] [wsgi:error] [pid 15344:tid 140570447054592]     raise value.with_traceback(tb)
[Thu Nov 16 21:40:57.180910 2017] [wsgi:error] [pid 15344:tid 140570447054592]   File "/usr/local/lib/python3.5/dist-packages/django/db/backends/utils.py", line 64, in execute
[Thu Nov 16 21:40:57.180917 2017] [wsgi:error] [pid 15344:tid 140570447054592]     return self.cursor.execute(sql, params)
[Thu Nov 16 21:40:57.180921 2017] [wsgi:error] [pid 15344:tid 140570447054592]   File "/usr/local/lib/python3.5/dist-packages/django/db/backends/sqlite3/base.py", line 337, in execute
[Thu Nov 16 21:40:57.180924 2017] [wsgi:error] [pid 15344:tid 140570447054592]     return Database.Cursor.execute(self, query, params)
[Thu Nov 16 21:40:57.180930 2017] [wsgi:error] [pid 15344:tid 140570447054592] django.db.utils.OperationalError: attempt to write a readonly database
[Thu Nov 16 21:40:57.180939 2017] [wsgi:error] [pid 15344:tid 140570447054592] 
[Thu Nov 16 21:54:23.013192 2017] [wsgi:error] [pid 15344:tid 140570447054592] Not Found: /Testline_Details/edit/
[Thu Nov 16 21:55:15.709586 2017] [wsgi:error] [pid 15344:tid 140570447054592] Not Found: /Testline_Details/admin
